{"trial_id": "1", "hyperparameters": {"space": [{"class_name": "Choice", "config": {"name": "activation", "default": "relu", "conditions": [], "values": ["relu", "tanh"], "ordered": false}}, {"class_name": "Int", "config": {"name": "num_neurons", "default": null, "conditions": [], "min_value": 1, "max_value": 30, "step": 5, "sampling": "linear"}}, {"class_name": "Int", "config": {"name": "num_hidden_layers", "default": 2, "conditions": [], "min_value": 1, "max_value": 5, "step": 1, "sampling": "linear"}}, {"class_name": "Int", "config": {"name": "num_units", "default": 16, "conditions": [], "min_value": 1, "max_value": 30, "step": 1, "sampling": "linear"}}], "values": {"activation": "tanh", "num_neurons": 26, "num_hidden_layers": 3, "num_units": 13}}, "metrics": {"metrics": {}}, "score": null, "best_step": 0, "status": "FAILED", "message": "Traceback (most recent call last):\n  File \"C:\\Users\\tamik\\anaconda3\\envs\\bootcamp3\\lib\\site-packages\\keras_tuner\\src\\engine\\base_tuner.py\", line 273, in _try_run_and_update_trial\n    self._run_and_update_trial(trial, *fit_args, **fit_kwargs)\n  File \"C:\\Users\\tamik\\anaconda3\\envs\\bootcamp3\\lib\\site-packages\\keras_tuner\\src\\engine\\base_tuner.py\", line 238, in _run_and_update_trial\n    results = self.run_trial(trial, *fit_args, **fit_kwargs)\n  File \"C:\\Users\\tamik\\anaconda3\\envs\\bootcamp3\\lib\\site-packages\\keras_tuner\\src\\engine\\tuner.py\", line 314, in run_trial\n    obj_value = self._build_and_fit_model(trial, *args, **copied_kwargs)\n  File \"C:\\Users\\tamik\\anaconda3\\envs\\bootcamp3\\lib\\site-packages\\keras_tuner\\src\\engine\\tuner.py\", line 233, in _build_and_fit_model\n    results = self.hypermodel.fit(hp, model, *args, **kwargs)\n  File \"C:\\Users\\tamik\\anaconda3\\envs\\bootcamp3\\lib\\site-packages\\keras_tuner\\src\\engine\\hypermodel.py\", line 149, in fit\n    return model.fit(*args, **kwargs)\n  File \"C:\\Users\\tamik\\anaconda3\\envs\\bootcamp3\\lib\\site-packages\\keras\\src\\utils\\traceback_utils.py\", line 70, in error_handler\n    raise e.with_traceback(filtered_tb) from None\n  File \"C:\\Users\\tamik\\AppData\\Local\\Temp\\__autograph_generated_file5id2u8q4.py\", line 15, in tf__train_function\n    retval_ = ag__.converted_call(ag__.ld(step_function), (ag__.ld(self), ag__.ld(iterator)), None, fscope)\nValueError: in user code:\n\n    File \"C:\\Users\\tamik\\anaconda3\\envs\\bootcamp3\\lib\\site-packages\\keras\\src\\engine\\training.py\", line 1377, in train_function  *\n        return step_function(self, iterator)\n    File \"C:\\Users\\tamik\\anaconda3\\envs\\bootcamp3\\lib\\site-packages\\keras\\src\\engine\\training.py\", line 1360, in step_function  **\n        outputs = model.distribute_strategy.run(run_step, args=(data,))\n    File \"C:\\Users\\tamik\\anaconda3\\envs\\bootcamp3\\lib\\site-packages\\keras\\src\\engine\\training.py\", line 1349, in run_step  **\n        outputs = model.train_step(data)\n    File \"C:\\Users\\tamik\\anaconda3\\envs\\bootcamp3\\lib\\site-packages\\keras\\src\\engine\\training.py\", line 1126, in train_step\n        y_pred = self(x, training=True)\n    File \"C:\\Users\\tamik\\anaconda3\\envs\\bootcamp3\\lib\\site-packages\\keras\\src\\utils\\traceback_utils.py\", line 70, in error_handler\n        raise e.with_traceback(filtered_tb) from None\n    File \"C:\\Users\\tamik\\anaconda3\\envs\\bootcamp3\\lib\\site-packages\\keras\\src\\engine\\input_spec.py\", line 298, in assert_input_compatibility\n        raise ValueError(\n\n    ValueError: Input 0 of layer \"sequential\" is incompatible with the layer: expected shape=(None, 34), found shape=(None, 43)\n\n"}